<?xml version="1.0"?>
<!-- Generated by Google Gemini-->
<robot name="dobot_magician_lite">

  <material name="white">
    <color rgba="0.9 0.9 0.9 1"/>
  </material>
  <material name="black">
    <color rgba="0.2 0.2 0.2 1"/>
  </material>

  <link name="base_link">
    <visual>
      <geometry>
        <cylinder radius="0.07" length="0.05"/>
      </geometry>
      <origin xyz="0 0 0.025" rpy="0 0 0"/>
      <material name="white"/>
    </visual>
  </link>

  <joint name="joint1" type="revolute">
    <parent link="base_link"/>
    <child link="link1"/>
    <origin xyz="0 0 0.05" rpy="0 0 0"/>
    <axis xyz="0 0 1"/>
    <limit lower="-2.35" upper="2.35" effort="10.0" velocity="1.0"/>
  </joint>

  <link name="link1">
    <visual>
      <geometry>
        <cylinder radius="0.06" length="0.06"/>
      </geometry>
      <origin xyz="0 0 0.03" rpy="0 0 0"/>
      <material name="black"/>
    </visual>
  </link>

  <joint name="joint2" type="revolute">
    <parent link="link1"/>
    <child link="link2"/>
    <origin xyz="0 0 0.06" rpy="0 0 0"/>
    <axis xyz="0 1 0"/>
    <limit lower="-0.08" upper="1.48" effort="10.0" velocity="1.0"/>
  </joint>

  <link name="link2">
    <visual>
      <geometry>
        <box size="0.04 0.04 0.15"/>
      </geometry>
      <origin xyz="0 0 0.075" rpy="0 0 0"/>
      <material name="white"/>
    </visual>
  </link>

  <joint name="joint3" type="revolute">
    <parent link="link2"/>
    <child link="link3"/>
    <origin xyz="0 0 0.15" rpy="0 0 0"/>
    <axis xyz="0 1 0"/>
    <limit lower="-0.17" upper="1.57" effort="10.0" velocity="1.0"/>
  </joint>

  <link name="link3">
    <visual>
      <geometry>
        <box size="0.15 0.03 0.03"/>
      </geometry>
      <origin xyz="0.075 0 0" rpy="0 0 0"/>
      <material name="black"/>
    </visual>
  </link>

  <link name="dummy_leveling_link"/>

  <joint name="passive_leveling_joint1" type="revolute">
    <parent link="link3"/>
    <child link="dummy_leveling_link"/>
    <origin xyz="0.15 0 0" rpy="0 0 0"/>
    <axis xyz="0 1 0"/>
    <limit lower="-3.14" upper="3.14" effort="10.0" velocity="1.0"/>
    <mimic joint="joint2" multiplier="-1.0" offset="0.0"/>
  </joint>

  <link name="level_wrist_link">
    <visual>
      <geometry>
        <box size="0.03 0.03 0.03"/>
      </geometry>
      <origin xyz="0 0 0" rpy="0 0 0"/>
      <material name="black"/>
    </visual>
  </link>

  <joint name="passive_leveling_joint2" type="revolute">
    <parent link="dummy_leveling_link"/>
    <child link="level_wrist_link"/>
    <origin xyz="0 0 0" rpy="0 0 0"/>
    <axis xyz="0 1 0"/>
    <limit lower="-3.14" upper="3.14" effort="10.0" velocity="1.0"/>
    <mimic joint="joint3" multiplier="-1.0" offset="0.0"/>
  </joint>

  <joint name="joint4" type="revolute">
    <parent link="level_wrist_link"/>
    <child link="end_effector"/>
    <origin xyz="0 0 -0.015" rpy="0 0 0"/>
    <axis xyz="0 0 1"/> 
    <limit lower="-2.5" upper="2.5" effort="10.0" velocity="1.0"/>
  </joint>

  <link name="end_effector">
    <visual>
      <geometry>
        <cylinder radius="0.015" length="0.04"/>
      </geometry>
      <origin xyz="0 0 -0.02" rpy="0 0 0"/>
      <material name="white"/>
    </visual>
  </link>

</robot>